<?xml version="1.0" ?>
<!-- =================================================================================== -->
<!-- |    This document was autogenerated by xacro from cc8.xacro                      | -->
<!-- |    EDITING THIS FILE BY HAND IS NOT RECOMMENDED                                 | -->
<!-- =================================================================================== -->
<robot name="cc8">
  <material name="silver">
    <color rgba="0.700 0.700 0.700 1.000"/>
  </material>
  <transmission name="rocker_joint_L_tran">
    <type>transmission_interface/SimpleTransmission</type>
    <joint name="rocker_joint_L">
      <hardwareInterface>hardware_interface/EffortJointInterface</hardwareInterface>
    </joint>
    <actuator name="rocker_joint_L_actr">
      <hardwareInterface>hardware_interface/EffortJointInterface</hardwareInterface>
      <mechanicalReduction>1</mechanicalReduction>
    </actuator>
  </transmission>
  <transmission name="steering_FL_tran">
    <type>transmission_interface/SimpleTransmission</type>
    <joint name="steering_FL">
      <hardwareInterface>hardware_interface/EffortJointInterface</hardwareInterface>
    </joint>
    <actuator name="steering_FL_actr">
      <hardwareInterface>hardware_interface/EffortJointInterface</hardwareInterface>
      <mechanicalReduction>1</mechanicalReduction>
    </actuator>
  </transmission>
  <transmission name="wheel_joint_FL_tran">
    <type>transmission_interface/SimpleTransmission</type>
    <joint name="wheel_joint_FL">
      <hardwareInterface>hardware_interface/EffortJointInterface</hardwareInterface>
    </joint>
    <actuator name="wheel_joint_FL_actr">
      <hardwareInterface>hardware_interface/EffortJointInterface</hardwareInterface>
      <mechanicalReduction>1</mechanicalReduction>
    </actuator>
  </transmission>
  <transmission name="bogie_joint_L_tran">
    <type>transmission_interface/SimpleTransmission</type>
    <joint name="bogie_joint_L">
      <hardwareInterface>hardware_interface/EffortJointInterface</hardwareInterface>
    </joint>
    <actuator name="bogie_joint_L_actr">
      <hardwareInterface>hardware_interface/EffortJointInterface</hardwareInterface>
      <mechanicalReduction>1</mechanicalReduction>
    </actuator>
  </transmission>
  <transmission name="wheel_joint_ML_tran">
    <type>transmission_interface/SimpleTransmission</type>
    <joint name="wheel_joint_ML">
      <hardwareInterface>hardware_interface/EffortJointInterface</hardwareInterface>
    </joint>
    <actuator name="wheel_joint_ML_actr">
      <hardwareInterface>hardware_interface/EffortJointInterface</hardwareInterface>
      <mechanicalReduction>1</mechanicalReduction>
    </actuator>
  </transmission>
  <transmission name="steering_RL_tran">
    <type>transmission_interface/SimpleTransmission</type>
    <joint name="steering_RL">
      <hardwareInterface>hardware_interface/EffortJointInterface</hardwareInterface>
    </joint>
    <actuator name="steering_RL_actr">
      <hardwareInterface>hardware_interface/EffortJointInterface</hardwareInterface>
      <mechanicalReduction>1</mechanicalReduction>
    </actuator>
  </transmission>
  <transmission name="wheel_joint_RL_tran">
    <type>transmission_interface/SimpleTransmission</type>
    <joint name="wheel_joint_RL">
      <hardwareInterface>hardware_interface/EffortJointInterface</hardwareInterface>
    </joint>
    <actuator name="wheel_joint_RL_actr">
      <hardwareInterface>hardware_interface/EffortJointInterface</hardwareInterface>
      <mechanicalReduction>1</mechanicalReduction>
    </actuator>
  </transmission>
  <transmission name="rocker_joint_R_tran">
    <type>transmission_interface/SimpleTransmission</type>
    <joint name="rocker_joint_R">
      <hardwareInterface>hardware_interface/EffortJointInterface</hardwareInterface>
    </joint>
    <actuator name="rocker_joint_R_actr">
      <hardwareInterface>hardware_interface/EffortJointInterface</hardwareInterface>
      <mechanicalReduction>1</mechanicalReduction>
    </actuator>
  </transmission>
  <transmission name="steering_FR_tran">
    <type>transmission_interface/SimpleTransmission</type>
    <joint name="steering_FR">
      <hardwareInterface>hardware_interface/EffortJointInterface</hardwareInterface>
    </joint>
    <actuator name="steering_FR_actr">
      <hardwareInterface>hardware_interface/EffortJointInterface</hardwareInterface>
      <mechanicalReduction>1</mechanicalReduction>
    </actuator>
  </transmission>
  <transmission name="wheel_joint_FR_tran">
    <type>transmission_interface/SimpleTransmission</type>
    <joint name="wheel_joint_FR">
      <hardwareInterface>hardware_interface/EffortJointInterface</hardwareInterface>
    </joint>
    <actuator name="wheel_joint_FR_actr">
      <hardwareInterface>hardware_interface/EffortJointInterface</hardwareInterface>
      <mechanicalReduction>1</mechanicalReduction>
    </actuator>
  </transmission>
  <transmission name="bogie_joint_R_tran">
    <type>transmission_interface/SimpleTransmission</type>
    <joint name="bogie_joint_R">
      <hardwareInterface>hardware_interface/EffortJointInterface</hardwareInterface>
    </joint>
    <actuator name="bogie_joint_R_actr">
      <hardwareInterface>hardware_interface/EffortJointInterface</hardwareInterface>
      <mechanicalReduction>1</mechanicalReduction>
    </actuator>
  </transmission>
  <transmission name="wheel_joint_MR_tran">
    <type>transmission_interface/SimpleTransmission</type>
    <joint name="wheel_joint_MR">
      <hardwareInterface>hardware_interface/EffortJointInterface</hardwareInterface>
    </joint>
    <actuator name="wheel_joint_MR_actr">
      <hardwareInterface>hardware_interface/EffortJointInterface</hardwareInterface>
      <mechanicalReduction>1</mechanicalReduction>
    </actuator>
  </transmission>
  <transmission name="steering_RR_tran">
    <type>transmission_interface/SimpleTransmission</type>
    <joint name="steering_RR">
      <hardwareInterface>hardware_interface/EffortJointInterface</hardwareInterface>
    </joint>
    <actuator name="steering_RR_actr">
      <hardwareInterface>hardware_interface/EffortJointInterface</hardwareInterface>
      <mechanicalReduction>1</mechanicalReduction>
    </actuator>
  </transmission>
  <transmission name="wheel_joint_RR_tran">
    <type>transmission_interface/SimpleTransmission</type>
    <joint name="wheel_joint_RR">
      <hardwareInterface>hardware_interface/EffortJointInterface</hardwareInterface>
    </joint>
    <actuator name="wheel_joint_RR_actr">
      <hardwareInterface>hardware_interface/EffortJointInterface</hardwareInterface>
      <mechanicalReduction>1</mechanicalReduction>
    </actuator>
  </transmission>
  <link name="base_footprint"/>
  <link name="base_link">
    <inertial>
      <origin rpy="0 0 0" xyz="0.02032158150481281 -0.004132938366153829 0.07847355896271041"/>
      <mass value="31.735326359935303"/>
      <inertia ixx="1.335922" ixy="0.030729" ixz="-0.074555" iyy="2.200752" iyz="0.009644" izz="3.295698"/>
    </inertial>
    <visual>
      <origin rpy="0 0 0" xyz="0 0 0"/>
      <geometry>
        <mesh filename="package://cc8_description/meshes/base_link.stl" scale="0.001 0.001 0.001"/>
      </geometry>
      <material name="silver"/>
    </visual>
    <collision>
      <origin rpy="0 0 0" xyz="0 0 0"/>
      <geometry>
        <mesh filename="package://cc8_description/meshes/base_link.stl" scale="0.001 0.001 0.001"/>
      </geometry>
    </collision>
  </link>
  <link name="case_link_L_1">
    <inertial>
      <origin rpy="0 0 0" xyz="-5.76305672645475e-05 -0.018384505977135424 -0.07500000038013135"/>
      <mass value="1.1591556289566074"/>
      <inertia ixx="0.002558" ixy="1e-06" ixz="-0.0" iyy="0.002056" iyz="0.0" izz="0.001807"/>
    </inertial>
    <visual>
      <origin rpy="0 0 0" xyz="-0.0 -0.275 -0.15"/>
      <geometry>
        <mesh filename="package://cc8_description/meshes/case_link_L_1.stl" scale="0.001 0.001 0.001"/>
      </geometry>
      <material name="silver"/>
    </visual>
    <collision>
      <origin rpy="0 0 0" xyz="-0.0 -0.275 -0.15"/>
      <geometry>
        <mesh filename="package://cc8_description/meshes/case_link_L_1.stl" scale="0.001 0.001 0.001"/>
      </geometry>
    </collision>
  </link>
  <link name="case_link_R_1">
    <inertial>
      <origin rpy="0 0 0" xyz="5.763056728314002e-05 0.018384505977134258 -0.07500000038013133"/>
      <mass value="1.1591556289566074"/>
      <inertia ixx="0.002558" ixy="1e-06" ixz="0.0" iyy="0.002056" iyz="-0.0" izz="0.001807"/>
    </inertial>
    <visual>
      <origin rpy="0 0 0" xyz="0.0 0.275 -0.15"/>
      <geometry>
        <mesh filename="package://cc8_description/meshes/case_link_R_1.stl" scale="0.001 0.001 0.001"/>
      </geometry>
      <material name="silver"/>
    </visual>
    <collision>
      <origin rpy="0 0 0" xyz="0.0 0.275 -0.15"/>
      <geometry>
        <mesh filename="package://cc8_description/meshes/case_link_R_1.stl" scale="0.001 0.001 0.001"/>
      </geometry>
    </collision>
  </link>
  <link name="rocker_L_1">
    <inertial>
      <origin rpy="0 0 0" xyz="0.2902240049859415 0.0708119772157999 0.021743637980664074"/>
      <mass value="2.996960457028018"/>
      <inertia ixx="0.018192" ixy="-0.019888" ixz="-0.030683" iyy="0.219444" iyz="-0.003026" izz="0.208276"/>
    </inertial>
    <visual>
      <origin rpy="0 0 0" xyz="-0.0 -0.2965 -0.075"/>
      <geometry>
        <mesh filename="package://cc8_description/meshes/rocker_L_1.stl" scale="0.001 0.001 0.001"/>
      </geometry>
      <material name="silver"/>
    </visual>
    <collision>
      <origin rpy="0 0 0" xyz="-0.0 -0.2965 -0.075"/>
      <geometry>
        <mesh filename="package://cc8_description/meshes/rocker_L_1.stl" scale="0.001 0.001 0.001"/>
      </geometry>
    </collision>
  </link>
  <link name="steering_fork_FL_1">
    <inertial>
      <origin rpy="0 0 0" xyz="-6.885276269119611e-05 -0.011024168785901178 -0.09406157894668771"/>
      <mass value="2.4293480883478487"/>
      <inertia ixx="0.02426" ixy="-1.3e-05" ixz="-1.5e-05" iyy="0.022285" iyz="-0.002519" izz="0.004801"/>
    </inertial>
    <visual>
      <origin rpy="0 0 0" xyz="-0.496003 -0.3905 -0.029299"/>
      <geometry>
        <mesh filename="package://cc8_description/meshes/steering_fork_FL_1.stl" scale="0.001 0.001 0.001"/>
      </geometry>
      <material name="silver"/>
    </visual>
    <collision>
      <origin rpy="0 0 0" xyz="-0.496003 -0.3905 -0.029299"/>
      <geometry>
        <mesh filename="package://cc8_description/meshes/steering_fork_FL_1.stl" scale="0.001 0.001 0.001"/>
      </geometry>
    </collision>
  </link>
  <link name="wheel_FL_1">
    <inertial>
      <origin rpy="0 0 0" xyz="-1.1388936826950413e-07 -0.05426775742438028 4.641033480856649e-07"/>
      <mass value="1.1863355806975049"/>
      <inertia ixx="0.003179" ixy="-0.0" ixz="0.0" iyy="0.004566" iyz="0.0" izz="0.003179"/>
    </inertial>
    <visual>
      <origin rpy="0 0 0" xyz="-0.496003 -0.4495 0.160201"/>
      <geometry>
        <mesh filename="package://cc8_description/meshes/wheel_FL_1.stl" scale="0.001 0.001 0.001"/>
      </geometry>
      <material name="silver"/>
    </visual>
    <collision>
      <origin rpy="1.5707963267948966 0 0" xyz="0.0 -0.06 0.0"/>
      <!--<geometry>
      <mesh filename="package://cc8_description/meshes/wheel_RR_1.stl" scale="0.001 0.001 0.001"/>
    </geometry>-->
      <geometry>
        <cylinder length="0.09" radius="0.09"/>
      </geometry>
    </collision>
  </link>
  <link name="bogie_L_1">
    <inertial>
      <origin rpy="0 0 0" xyz="-0.09314608246660502 0.03332407904328044 0.009125614751943794"/>
      <mass value="3.563528887834295"/>
      <inertia ixx="0.058221" ixy="-0.002773" ixz="0.081537" iyy="0.208547" iyz="0.001886" izz="0.157317"/>
    </inertial>
    <visual>
      <origin rpy="0 0 0" xyz="0.211097 -0.383131 -0.015175"/>
      <geometry>
        <mesh filename="package://cc8_description/meshes/bogie_L_1.stl" scale="0.001 0.001 0.001"/>
      </geometry>
      <material name="silver"/>
    </visual>
    <collision>
      <origin rpy="0 0 0" xyz="0.211097 -0.383131 -0.015175"/>
      <geometry>
        <mesh filename="package://cc8_description/meshes/bogie_L_1.stl" scale="0.001 0.001 0.001"/>
      </geometry>
    </collision>
  </link>
  <link name="wheel_ML_1">
    <inertial>
      <origin rpy="0 0 0" xyz="3.282565275457885e-07 -0.0542676471666968 -1.748023029657375e-07"/>
      <mass value="1.1863355806975049"/>
      <inertia ixx="0.003179" ixy="-0.0" ixz="0.0" iyy="0.004566" iyz="0.0" izz="0.003179"/>
    </inertial>
    <visual>
      <origin rpy="0 0 0" xyz="5e-05 -0.504568 0.160663"/>
      <geometry>
        <mesh filename="package://cc8_description/meshes/wheel_ML_1.stl" scale="0.001 0.001 0.001"/>
      </geometry>
      <material name="silver"/>
    </visual>
    <collision>
      <origin rpy="1.5707963267948966 0 0" xyz="0.0 -0.06 0.0"/>
      <!--<geometry>
      <mesh filename="package://cc8_description/meshes/wheel_RR_1.stl" scale="0.001 0.001 0.001"/>
    </geometry>-->
      <geometry>
        <cylinder length="0.09" radius="0.09"/>
      </geometry>
    </collision>
  </link>
  <link name="steering_fork_RL_1">
    <inertial>
      <origin rpy="0 0 0" xyz="-6.889446618985051e-05 -0.011024058527650371 -0.09406208347131854"/>
      <mass value="2.4293480883478487"/>
      <inertia ixx="0.02426" ixy="-1.3e-05" ixz="-1.5e-05" iyy="0.022285" iyz="-0.002519" izz="0.004801"/>
    </inertial>
    <visual>
      <origin rpy="0 0 0" xyz="0.503097 -0.414731 -0.025175"/>
      <geometry>
        <mesh filename="package://cc8_description/meshes/steering_fork_RL_1.stl" scale="0.001 0.001 0.001"/>
      </geometry>
      <material name="silver"/>
    </visual>
    <collision>
      <origin rpy="0 0 0" xyz="0.503097 -0.414731 -0.025175"/>
      <geometry>
        <mesh filename="package://cc8_description/meshes/steering_fork_RL_1.stl" scale="0.001 0.001 0.001"/>
      </geometry>
    </collision>
  </link>
  <link name="wheel_RL_1">
    <inertial>
      <origin rpy="0 0 0" xyz="-1.5559286714594833e-07 -0.05426764716612953 -4.0421283015179554e-08"/>
      <mass value="1.1863355806975049"/>
      <inertia ixx="0.003179" ixy="-0.0" ixz="0.0" iyy="0.004566" iyz="0.0" izz="0.003179"/>
    </inertial>
    <visual>
      <origin rpy="0 0 0" xyz="0.503097 -0.473731 0.164325"/>
      <geometry>
        <mesh filename="package://cc8_description/meshes/wheel_RL_1.stl" scale="0.001 0.001 0.001"/>
      </geometry>
      <material name="silver"/>
    </visual>
    <collision>
      <origin rpy="1.5707963267948966 0 0" xyz="0.0 -0.06 0.0"/>
      <!--<geometry>
      <mesh filename="package://cc8_description/meshes/wheel_RR_1.stl" scale="0.001 0.001 0.001"/>
    </geometry>-->
      <geometry>
        <cylinder length="0.09" radius="0.09"/>
      </geometry>
    </collision>
  </link>
  <link name="rocker_R_1">
    <inertial>
      <origin rpy="0 0 0" xyz="0.2902238062893875 -0.06841948402815423 0.02174359272823953"/>
      <mass value="2.996961698235828"/>
      <inertia ixx="0.017884" ixy="0.018413" ixz="-0.030683" iyy="0.219444" iyz="0.002496" izz="0.207968"/>
    </inertial>
    <visual>
      <origin rpy="0 0 0" xyz="0.0 0.2965 -0.075"/>
      <geometry>
        <mesh filename="package://cc8_description/meshes/rocker_R_1.stl" scale="0.001 0.001 0.001"/>
      </geometry>
      <material name="silver"/>
    </visual>
    <collision>
      <origin rpy="0 0 0" xyz="0.0 0.2965 -0.075"/>
      <geometry>
        <mesh filename="package://cc8_description/meshes/rocker_R_1.stl" scale="0.001 0.001 0.001"/>
      </geometry>
    </collision>
  </link>
  <link name="steering_fork_FR_1">
    <inertial>
      <origin rpy="0 0 0" xyz="6.885206036416625e-05 0.011024168785899957 -0.09406157894668979"/>
      <mass value="2.42934808834785"/>
      <inertia ixx="0.02426" ixy="-1.3e-05" ixz="1.5e-05" iyy="0.022285" iyz="0.002519" izz="0.004801"/>
    </inertial>
    <visual>
      <origin rpy="0 0 0" xyz="-0.496003 0.3905 -0.029299"/>
      <geometry>
        <mesh filename="package://cc8_description/meshes/steering_fork_FR_1.stl" scale="0.001 0.001 0.001"/>
      </geometry>
      <material name="silver"/>
    </visual>
    <collision>
      <origin rpy="0 0 0" xyz="-0.496003 0.3905 -0.029299"/>
      <geometry>
        <mesh filename="package://cc8_description/meshes/steering_fork_FR_1.stl" scale="0.001 0.001 0.001"/>
      </geometry>
    </collision>
  </link>
  <link name="wheel_FR_1">
    <inertial>
      <origin rpy="0 0 0" xyz="-1.2726399756246565e-07 0.05426787444710596 3.4046564675871416e-07"/>
      <mass value="1.1863358649901974"/>
      <inertia ixx="0.003179" ixy="-0.0" ixz="-0.0" iyy="0.004566" iyz="0.0" izz="0.003179"/>
    </inertial>
    <visual>
      <origin rpy="0 0 0" xyz="-0.496003 0.4495 0.160201"/>
      <geometry>
        <mesh filename="package://cc8_description/meshes/wheel_FR_1.stl" scale="0.001 0.001 0.001"/>
      </geometry>
      <material name="silver"/>
    </visual>
    <collision>
      <origin rpy="1.5707963267948966 0 0" xyz="0.0 0.06 0.0"/>
      <!--<geometry>
      <mesh filename="package://cc8_description/meshes/wheel_RR_1.stl" scale="0.001 0.001 0.001"/>
    </geometry>-->
      <geometry>
        <cylinder length="0.09" radius="0.09"/>
      </geometry>
    </collision>
  </link>
  <link name="bogie_R_1">
    <inertial>
      <origin rpy="0 0 0" xyz="-0.09314608227719093 -0.03332407904097906 0.009125614666047022"/>
      <mass value="3.563528891417035"/>
      <inertia ixx="0.058221" ixy="0.002773" ixz="0.081537" iyy="0.208547" iyz="-0.001886" izz="0.157317"/>
    </inertial>
    <visual>
      <origin rpy="0 0 0" xyz="0.211097 0.383131 -0.015175"/>
      <geometry>
        <mesh filename="package://cc8_description/meshes/bogie_R_1.stl" scale="0.001 0.001 0.001"/>
      </geometry>
      <material name="silver"/>
    </visual>
    <collision>
      <origin rpy="0 0 0" xyz="0.211097 0.383131 -0.015175"/>
      <geometry>
        <mesh filename="package://cc8_description/meshes/bogie_R_1.stl" scale="0.001 0.001 0.001"/>
      </geometry>
    </collision>
  </link>
  <link name="wheel_MR_1">
    <inertial>
      <origin rpy="0 0 0" xyz="3.148818914003169e-07 0.05426776418942242 -2.984400040983992e-07"/>
      <mass value="1.1863358649901974"/>
      <inertia ixx="0.003179" ixy="-0.0" ixz="-0.0" iyy="0.004566" iyz="0.0" izz="0.003179"/>
    </inertial>
    <visual>
      <origin rpy="0 0 0" xyz="5e-05 0.504568 0.160663"/>
      <geometry>
        <mesh filename="package://cc8_description/meshes/wheel_MR_1.stl" scale="0.001 0.001 0.001"/>
      </geometry>
      <material name="silver"/>
    </visual>
    <collision>
      <origin rpy="1.5707963267948966 0 0" xyz="0.0 0.06 0.0"/>
      <!--<geometry>
      <mesh filename="package://cc8_description/meshes/wheel_RR_1.stl" scale="0.001 0.001 0.001"/>
    </geometry>-->
      <geometry>
        <cylinder length="0.09" radius="0.09"/>
      </geometry>
    </collision>
  </link>
  <link name="steering_fork_RR_1">
    <inertial>
      <origin rpy="0 0 0" xyz="6.881035686501225e-05 0.01102405852764915 -0.09406208347132052"/>
      <mass value="2.42934808834785"/>
      <inertia ixx="0.02426" ixy="-1.3e-05" ixz="1.5e-05" iyy="0.022285" iyz="0.002519" izz="0.004801"/>
    </inertial>
    <visual>
      <origin rpy="0 0 0" xyz="0.503097 0.414731 -0.025175"/>
      <geometry>
        <mesh filename="package://cc8_description/meshes/steering_fork_RR_1.stl" scale="0.001 0.001 0.001"/>
      </geometry>
      <material name="silver"/>
    </visual>
    <collision>
      <origin rpy="0 0 0" xyz="0.503097 0.414731 -0.025175"/>
      <geometry>
        <mesh filename="package://cc8_description/meshes/steering_fork_RR_1.stl" scale="0.001 0.001 0.001"/>
      </geometry>
    </collision>
  </link>
  <link name="wheel_RR_1">
    <inertial>
      <origin rpy="0 0 0" xyz="-1.6896749654993215e-07 0.05426776418885526 -1.640589839813078e-07"/>
      <mass value="1.1863358649901974"/>
      <inertia ixx="0.003179" ixy="-0.0" ixz="-0.0" iyy="0.004566" iyz="0.0" izz="0.003179"/>
    </inertial>
    <visual>
      <origin rpy="0 0 0" xyz="0.503097 0.473731 0.164325"/>
      <geometry>
        <mesh filename="package://cc8_description/meshes/wheel_RR_1.stl" scale="0.001 0.001 0.001"/>
      </geometry>
      <material name="silver"/>
    </visual>
    <collision>
      <origin rpy="1.5707963267948966 0 0" xyz="0.0 0.06 0.0"/>
      <!--<geometry>
      <mesh filename="package://cc8_description/meshes/wheel_RR_1.stl" scale="0.001 0.001 0.001"/>
    </geometry>-->
      <geometry>
        <cylinder length="0.09" radius="0.09"/>
      </geometry>
    </collision>
  </link>
  <joint name="base_joint" type="fixed">
    <origin rpy="0 0 0" xyz="0 0 0.25"/>
    <parent link="base_footprint"/>
    <child link="base_link"/>
  </joint>
  <joint name="fixed_joint_L" type="fixed">
    <origin rpy="0 0 0" xyz="0.0 0.275 0.15"/>
    <parent link="base_link"/>
    <child link="case_link_L_1"/>
  </joint>
  <joint name="fixed_joint_R" type="fixed">
    <origin rpy="0 0 0" xyz="0.0 -0.275 0.15"/>
    <parent link="base_link"/>
    <child link="case_link_R_1"/>
  </joint>
  <joint name="rocker_joint_L" type="continuous">
    <origin rpy="0 0 0" xyz="0.0 0.0215 -0.075"/>
    <parent link="case_link_L_1"/>
    <child link="rocker_L_1"/>
    <axis xyz="0.0 1.0 -0.0"/>
    <dynamics damping="0.9" friction="1.0"/>
  </joint>
  <joint name="steering_FL" type="continuous">
    <origin rpy="0 0 0" xyz="0.496003 0.094 -0.045701"/>
    <parent link="rocker_L_1"/>
    <child link="steering_fork_FL_1"/>
    <axis xyz="0.0 0.0 -1.0"/>
  </joint>
  <joint name="wheel_joint_FL" type="continuous">
    <origin rpy="0 0 0" xyz="0.0 0.059 -0.1895"/>
    <parent link="steering_fork_FL_1"/>
    <child link="wheel_FL_1"/>
    <axis xyz="0.0 1.0 -0.0"/>
  </joint>
  <joint name="bogie_joint_L" type="continuous">
    <origin rpy="0 0 0" xyz="-0.211097 0.086631 -0.059825"/>
    <parent link="rocker_L_1"/>
    <child link="bogie_L_1"/>
    <axis xyz="-0.0 -1.0 0.0"/>
  </joint>
  <joint name="wheel_joint_ML" type="continuous">
    <origin rpy="0 0 0" xyz="0.211047 0.121437 -0.175838"/>
    <parent link="bogie_L_1"/>
    <child link="wheel_ML_1"/>
    <axis xyz="0.0 -1.0 0.0"/>
  </joint>
  <joint name="steering_RL" type="continuous">
    <origin rpy="0 0 0" xyz="-0.292 0.0316 0.01"/>
    <parent link="bogie_L_1"/>
    <child link="steering_fork_RL_1"/>
    <axis xyz="0.0 0.0 -1.0"/>
  </joint>
  <joint name="wheel_joint_RL" type="continuous">
    <origin rpy="0 0 0" xyz="0.0 0.059 -0.1895"/>
    <parent link="steering_fork_RL_1"/>
    <child link="wheel_RL_1"/>
    <axis xyz="0.0 1.0 -0.0"/>
  </joint>
  <joint name="rocker_joint_R" type="continuous">
    <origin rpy="0 0 0" xyz="0.0 -0.0215 -0.075"/>
    <parent link="case_link_R_1"/>
    <child link="rocker_R_1"/>
    <axis xyz="-0.0 -1.0 -0.0"/>
    <dynamics damping="0.9" friction="1.0"/>
    <mimic joint="rocker_joint_L"/>
  </joint>
  <joint name="steering_FR" type="continuous">
    <origin rpy="0 0 0" xyz="0.496003 -0.094 -0.045701"/>
    <parent link="rocker_R_1"/>
    <child link="steering_fork_FR_1"/>
    <axis xyz="0.0 -0.0 -1.0"/>
  </joint>
  <joint name="wheel_joint_FR" type="continuous">
    <origin rpy="0 0 0" xyz="0.0 -0.059 -0.1895"/>
    <parent link="steering_fork_FR_1"/>
    <child link="wheel_FR_1"/>
    <axis xyz="-0.0 -1.0 -0.0"/>
  </joint>
  <joint name="bogie_joint_R" type="continuous">
    <origin rpy="0 0 0" xyz="-0.211097 -0.086631 -0.059825"/>
    <parent link="rocker_R_1"/>
    <child link="bogie_R_1"/>
    <axis xyz="-0.0 -1.0 -0.0"/>
  </joint>
  <joint name="wheel_joint_MR" type="continuous">
    <origin rpy="0 0 0" xyz="0.211047 -0.121437 -0.175838"/>
    <parent link="bogie_R_1"/>
    <child link="wheel_MR_1"/>
    <axis xyz="-0.0 -1.0 -0.0"/>
  </joint>
  <joint name="steering_RR" type="continuous">
    <origin rpy="0 0 0" xyz="-0.292 -0.0316 0.01"/>
    <parent link="bogie_R_1"/>
    <child link="steering_fork_RR_1"/>
    <axis xyz="0.0 -0.0 -1.0"/>
  </joint>
  <joint name="wheel_joint_RR" type="continuous">
    <origin rpy="0 0 0" xyz="0.0 -0.059 -0.1895"/>
    <parent link="steering_fork_RR_1"/>
    <child link="wheel_RR_1"/>
    <axis xyz="-0.0 -1.0 -0.0"/>
  </joint>
</robot>

